Workbook

Sheet Assumptions
A1: School OS SaaS - Planning Assumptions
A2: Parameter | B2: Baseline | C2: Editable? | D2: Planning Impact | E2: Decision Status | F2: Notes
A3: Project start | B3: 46286 | C3: Yes | D3: Drives all baseline dates | E3: Baseline | F3: Start after requirements baseline
A4: Target GA | B4: 46860 | C4: Yes | D4: Full production release target | E4: Baseline | F4: Adjust after architecture estimation
A5: Delivery model | B5: Two-week sprints | C5: Yes | D5: Sprint planning and release cadence | E5: Confirmed | F5: Use milestone gates between major phases
A6: Primary client | B6: Flutter Windows (.exe) | C6: Yes | D6: Desktop-first delivery | E6: Confirmed | F6: Architecture should keep future clients possible
A7: Backend | B7: Supabase / PostgreSQL | C7: No | D7: Database, Auth, Storage, RLS, Edge Functions | E7: Confirmed | F7: One Supabase project per customer school
A8: SaaS deployment | B8: One school = one Supabase project | C8: No | D8: Strong tenant isolation | E8: Confirmed | F8: Shared SaaS control plane
A9: Team assumption | B9: 1 lead engineer + part-time QA/design/SME | C9: Yes | D9: Dates assume lean delivery capacity | E9: Planning assumption | F9: Add people to compress schedule
A10: Methodology | B10: Agile + architecture gates | C10: Yes | D10: Iterative delivery with controlled schema design | E10: Baseline | F10: Avoid rushing irreversible database decisions
A11: Languages | B11: English initially | C11: Yes | D11: Simplifies V1 UI | E11: Confirmed | F11: Keep localization-ready
A12: Deferred | B12: GPS, biometrics, camera/face recognition, RFID/NFC, inventory, WhatsApp, payment gateway | C12: Yes | D12: Keeps core release achievable | E12: Confirmed | F12: Architecture should not block later additions

Sheet Roadmap
A1: School OS SaaS - Product Roadmap
A3: Phase | B3: Name | C3: Start | D3: End | E3: Weeks | F3: Primary Outcome | G3: Release Gate | H3: Owner | I3: Status | J3: Progress % | K3: Dependencies | L3: Notes
A4: P0 | B4: Discovery & Project Setup | C4: 46286 | D4: 46311 | E4: 4 | F4: Freeze requirements baseline, PM system, repository and standards | G4: Requirements Baseline | H4: Product Owner / Lead | I4: Done | J4: 1 | K4: - | L4: Master requirements complete; PM package created
A5: P1 | B5: Architecture & SaaS Foundation | C5: 46314 | D5: 46367 | E5: 8 | F5: Control plane design, school project template, environments, DB conventions | G5: Architecture Gate | H5: Lead Engineer | I5: Done | J5: 1 | K5: P0 | L5: Do not build business modules before security and migration strategy
A6: P2 | B6: Identity, RBAC & Academic Foundation | C6: 46370 | D6: 46430 | E6: 9 | F6: Auth/account mapping, people, roles, scopes, campuses, academic years, class structure | G6: Foundation Alpha | H6: Lead Engineer | I6: Not Started | J6: 0 | K6: P1 | L6: Foundation used by every later module
A7: P3 | B7: Students, Families & Admissions | C7: 46433 | D7: 46486 | E7: 8 | F7: Student lifecycle, family accounts, admission workflow, enrollment history, promotion | G7: Student Core Alpha | H7: Lead Engineer | I7: Not Started | J7: 0 | K7: P2 | L7: Historical data model must be stable
A8: P4 | B8: Curriculum, Teachers & Timetable | C8: 46468 | D8: 46521 | E8: 8 | F8: Subjects, curriculum, teacher assignment and timetable generation | G8: Academic Alpha | H8: Lead Engineer | I8: Not Started | J8: 0 | K8: P2,P3 | L8: Overlaps student work after stable entities exist
A9: P5 | B9: Attendance, Homework & Notifications Core | C9: 46503 | D9: 46563 | E9: 9 | F9: Morning/break attendance, QR/manual flow, corrections, assignments and base notifications | G9: Operations Alpha | H9: Lead Engineer | I9: Not Started | J9: 0 | K9: P3,P4 | L9: Includes offline-ready attendance contracts
A10: P6 | B10: Exams, Marks & Results | C10: 46552 | D10: 46619 | E10: 10 | F10: Assessment engine, grading, result approvals, locking and report cards | G10: Academic Pilot | H10: Lead Engineer | I10: Not Started | J10: 0 | K10: P4,P5 | L10: Exam Controller publication gate
A11: P7 | B11: Fees, Payments & Finance | C11: 46608 | D11: 46682 | E11: 11 | F11: Fee structures, discounts, invoices, payment evidence, receipts, reversals, overdue | G11: School Beta | H11: Lead Engineer | I11: Not Started | J11: 0 | K11: P3,P6 | L11: Financial integrity and approvals mandatory
A12: P8 | B12: HR, Payroll & Leave | C12: 46664 | D12: 46717 | E12: 8 | F12: Employees, monthly payroll, bonuses, deductions, salary approvals, configurable leave | G12: Admin Beta | H12: Lead Engineer | I12: Not Started | J12: 0 | K12: P2,P7 | L12: Uses shared approval engine
A13: P9 | B13: Library, Transport, Hostel & Medical | C13: 46699 | D13: 46766 | E13: 10 | F13: Optional operational modules with permission isolation | G13: Feature Complete | H13: Lead Engineer | I13: Not Started | J13: 0 | K13: P3,P8 | L13: GPS/inventory remain deferred
A14: P10 | B14: Offline Sync, Backup & Hardening | C14: 46734 | D14: 46794 | E14: 9 | F14: Encrypted local storage, conflict detection, backup/restore, resilience | G14: Resilience Gate | H14: Lead Engineer / QA | I14: Not Started | J14: 0 | K14: P5,P7,P9 | L14: No silent overwrite of critical records
A15: P11 | B15: Analytics, Automation & AI | C15: 46769 | D15: 46829 | E15: 9 | F15: Dashboards, reports, event automation, permission-aware AI, conversation history | G15: Intelligence RC | H15: Lead Engineer | I15: Not Started | J15: 0 | K15: P6,P7,P10 | L15: AI must never bypass authorization
A16: P12 | B16: UAT, Security, Performance & Launch | C16: 46813 | D16: 46857 | E16: 7 | F16: End-to-end validation, migration test, UAT, production runbook and release | G16: GA Readiness | H16: Lead Engineer / QA | I16: Not Started | J16: 0 | K16: P1-P11 | L16: Production launch after gate approval

Sheet Task Register
A1: Detailed Work Breakdown Structure / Master Task Register
A3: ID | B3: Phase | C3: Workstream | D3: Task / Deliverable | E3: Start | F3: End | G3: Days | H3: Owner | I3: Priority | J3: Status | K3: Progress % | L3: Dependency | M3: Release | N3: Acceptance / Exit Criteria | O3: Risk Flag | P3: Notes | Q3: Last Update
A4: T001 | B4: P0 | C4: Product | D4: Requirements discovery and question log | E4: 46286 | F4: 46290 | G4: 5 | H4: Product Owner / Lead | I4: Critical | J4: Done | K4: 1 | M4: Requirements Baseline | N4: All major business questions recorded | Q4: 46284
A5: T002 | B5: P0 | C5: Product | D5: Master requirements & architecture specification v0.1 | E5: 46293 | F5: 46297 | G5: 5 | H5: Product Owner / Lead | I5: Critical | J5: Done | K5: 1 | L5: T001 | M5: Requirements Baseline | N5: Versioned master specification approved | Q5: 46284
A6: T003 | B6: P0 | C6: PM | D6: Project timeline, WBS, risks, RACI and governance baseline | E6: 46300 | F6: 46304 | G6: 5 | H6: Product Owner / Lead | I6: High | J6: Done | K6: 1 | L6: T002 | M6: Requirements Baseline | N6: PM workbook and management plan generated | Q6: 46284
A7: T004 | B7: P0 | C7: Engineering | D7: Repository layout, branching, coding standards and naming conventions | E7: 46307 | F7: 46311 | G7: 5 | H7: Lead Engineer | I7: High | J7: Not Started | K7: 0 | L7: T003 | M7: Architecture Gate | N7: Repository conventions documented | Q7: 46284
A8: T005 | B8: P1 | C8: Architecture | D8: Define SaaS control-plane responsibilities and school project boundaries | E8: 46314 | F8: 46318 | G8: 5 | H8: Lead Engineer | I8: Critical | J8: Not Started | K8: 0 | L8: T004 | M8: Architecture Gate | N8: Architecture decision recorded and testable | Q8: 46284
A9: T006 | B9: P1 | C9: Architecture | D9: Define environments: local/dev/staging/production | E9: 46314 | F9: 46325 | G9: 12 | H9: Lead Engineer | I9: High | J9: Not Started | K9: 0 | L9: T004 | M9: Architecture Gate | N9: Environment strategy documented | Q9: 46284
A10: T007 | B10: P1 | C10: Database | D10: Define PostgreSQL naming, IDs, timestamps, soft-delete and history conventions | E10: 46321 | F10: 46332 | G10: 12 | H10: Lead Engineer | I10: Critical | J10: Not Started | K10: 0 | L10: T005 | M10: Architecture Gate | N10: Database conventions approved | Q10: 46284
A11: T008 | B11: P1 | C11: Database | D11: Define migration strategy and schema-version tracking | E11: 46328 | F11: 46339 | G11: 12 | H11: Lead Engineer | I11: Critical | J11: Not Started | K11: 0 | L11: T007 | M11: Architecture Gate | N11: Migrations repeatable | Q11: 46284
A12: T009 | B12: P1 | C12: Security | D12: Define RLS architecture and server-side secret boundaries | E12: 46335 | F12: 46346 | G12: 12 | H12: Lead Engineer | I12: Critical | J12: Not Started | K12: 0 | L12: T007 | M12: Architecture Gate | N12: Default-deny security model approved | Q12: 46284
A13: T010 | B13: P1 | C13: Platform | D13: Define Storage buckets and private document access strategy | E13: 46342 | F13: 46353 | G13: 12 | H13: Lead Engineer | I13: High | J13: Not Started | K13: 0 | L13: T009 | M13: Architecture Gate | N13: Storage access patterns approved | Q13: 46284
A14: T011 | B14: P1 | C14: Platform | D14: Define Edge Function/service boundaries | E14: 46349 | F14: 46360 | G14: 12 | H14: Lead Engineer | I14: High | J14: Not Started | K14: 0 | L14: T009 | M14: Architecture Gate | N14: Server responsibilities documented | Q14: 46284
A15: T012 | B15: P1 | C15: Deployment | D15: Create reusable school-project bootstrap/migration sequence | E15: 46356 | F15: 46367 | G15: 12 | H15: Lead Engineer | I15: Critical | J15: Not Started | K15: 0 | L15: T008,T009,T010 | M15: Architecture Gate | N15: Fresh project can be provisioned reproducibly | Q15: 46284
A16: T013 | B16: P2 | C16: Identity | D16: Person/profile model separate from auth account | E16: 46370 | F16: 46380 | G16: 11 | H16: Lead Engineer | I16: Critical | J16: Not Started | K16: 0 | L16: T012 | M16: Foundation Alpha | N16: Schema + RLS tests pass | Q16: 46284
... A111: T108 | B111: P12 | C111: Release | D111: GA go/no-go review and production launch | E111: 46854 | F111: 46857 | G111: 4 | H111: Product Owner / Lead | I111: Critical | J111: Not Started | K111: 0 | L111: T106 | M111: GA Readiness | N111: Go/no-go signed | Q111: 46284

Sheet Milestones
A1: Major Milestones & Release Gates
A3: ID | B3: Milestone | C3: Target Date | D3: Phase | E3: Deliverable | F3: Approver | G3: Status | H3: Exit Criteria | I3: Next Step
A4: M01 | B4: Requirements Baseline | C4: 46311 | D4: P0 | E4: Master requirements + PM baseline approved | F4: Product Owner | G4: In Progress | H4: No unresolved architecture blockers | I4: Foundation may begin
A5: M02 | B5: Architecture Gate | C5: 46367 | D5: P1 | E5: SaaS, DB, RLS, storage, migration and deployment patterns approved | F5: Lead Engineer | G5: Not Started | H5: Architecture decision records complete | I5: Foundation coding approved
A6: M03 | B6: Foundation Alpha | C6: 46430 | D6: P2 | E6: Auth/RBAC/scope/campus/academic foundation working | F6: Lead Engineer | G6: Not Started | H6: Permission tests passing | I6: Student modules unlocked
A7: M04 | B7: Student Core Alpha | C7: 46486 | D7: P3 | E7: Admission, family, enrollment and promotion history working | F7: Lead Engineer | G7: Not Started | H7: History and transfer scenarios pass | I7: Academic operations unlocked
A8: M05 | B8: Operations Alpha | C8: 46563 | D8: P5 | E8: Timetable, attendance, homework and base notifications usable | F8: Lead Engineer | G8: Not Started | H8: Teacher workflow UAT pass | I8: Pilot academic operations
A9: M06 | B9: Academic Pilot | C9: 46619 | D9: P6 | E9: Exam/marks/results/report card workflow usable | F9: Exam Controller / Lead | G9: Not Started | H9: Publish-lock-correct lifecycle passes | I9: Pilot school use
A10: M07 | B10: School Beta | C10: 46682 | D10: P7 | E10: Finance and payments integrated with academic core | F10: Product Owner / Lead | G10: Not Started | H10: Financial reconciliation passes | I10: Broader beta
A11: M08 | B11: Feature Complete | C11: 46766 | D11: P9 | E11: Core optional modules completed | F11: Lead Engineer | G11: Not Started | H11: Module enable/disable validated | I11: Hardening begins
A12: M09 | B12: Resilience Gate | C12: 46794 | D12: P10 | E12: Offline sync, backup/restore and deployment rehearsal pass | F12: Lead Engineer / QA | G12: Not Started | H12: Failure recovery scenarios pass | I12: RC eligible
A13: M10 | B13: Intelligence RC | C13: 46829 | D13: P11 | E13: Analytics, automation and permission-aware AI complete | F13: Product Owner / Lead | G13: Not Started | H13: AI authorization tests pass | I13: Release candidate
A14: M11 | B14: GA Readiness | C14: 46857 | D14: P12 | E14: UAT, security, performance and documentation gates pass | F14: Product Owner | G14: Not Started | H14: No unresolved critical defects | I14: Approve production
A15: M12 | B15: General Availability | C15: 46860 | D15: Release | E15: Production release | F15: Product Owner | G15: Not Started | H15: Go/no-go signed | I15: Operate/support

Sheet Sprints
A1: Two-Week Sprint Calendar
A3: Sprint | B3: Start | C3: End | D3: Primary Phase | E3: Suggested Focus | F3: Release / Gate | G3: Status | H3: Notes
A4: S01 | B4: 46286 | C4: 46299 | D4: P0 | E4: Requirements, PM setup, repo standards | G4: Planned
A5: S02 | B5: 46300 | C5: 46313 | D5: P0 | E5: Requirements, PM setup, repo standards | F5: Requirements Baseline | G5: Planned
A6: S03 | B6: 46314 | C6: 46327 | D6: P1 | E6: Architecture, migrations, RLS, control plane | G6: Planned
A7: S04 | B7: 46328 | C7: 46341 | D7: P1 | E7: Architecture, migrations, RLS, control plane | G7: Planned
A8: S05 | B8: 46342 | C8: 46355 | D8: P1 | E8: Architecture, migrations, RLS, control plane | G8: Planned
A9: S06 | B9: 46356 | C9: 46369 | D9: P1 | E9: Architecture, migrations, RLS, control plane | F9: Architecture Gate | G9: Planned
A10: S07 | B10: 46370 | C10: 46383 | D10: P2 | E10: Auth, people, RBAC, campus, academic setup | G10: Planned
A11: S08 | B11: 46384 | C11: 46397 | D11: P2 | E11: Auth, people, RBAC, campus, academic setup | G11: Planned
A12: S09 | B12: 46398 | C12: 46411 | D12: P2 | E12: Auth, people, RBAC, campus, academic setup | G12: Planned
A13: S10 | B13: 46412 | C13: 46425 | D13: P2 | E13: Auth, people, RBAC, campus, academic setup | G13: Planned
A14: S11 | B14: 46426 | C14: 46439 | D14: Launch/Support | E14: Integration | F14: Foundation Alpha | G14: Planned
A15: S12 | B15: 46440 | C15: 46453 | D15: P3 | E15: Students, family, admissions, enrollment | G15: Planned
A16: S13 | B16: 46454 | C16: 46467 | D16: P3 | E16: Students, family, admissions, enrollment | G16: Planned
A17: S14 | B17: 46468 | C17: 46481 | D17: P3, P4 | E17: Students, family, admissions, enrollment + Curriculum, teachers, timetable | G17: Planned
A18: S15 | B18: 46482 | C18: 46495 | D18: P4 | E18: Curriculum, teachers, timetable | F18: Student Core Alpha | G18: Planned
A19: S16 | B19: 46496 | C19: 46509 | D19: P4 | E19: Curriculum, teachers, timetable | G19: Planned
A20: S17 | B20: 46510 | C20: 46523 | D20: P4, P5 | E20: Curriculum, teachers, timetable + Attendance, assignments, notifications | G20: Planned
A21: S18 | B21: 46524 | C21: 46537 | D21: P5 | E21: Attendance, assignments, notifications | G21: Planned
A22: S19 | B22: 46538 | C22: 46551 | D22: P5 | E22: Attendance, assignments, notifications | G22: Planned
A23: S20 | B23: 46552 | C23: 46565 | D23: P5, P6 | E23: Attendance, assignments, notifications + Exams, marks, results | F23: Operations Alpha | G23: Planned
A24: S21 | B24: 46566 | C24: 46579 | D24: P6 | E24: Exams, marks, results | G24: Planned
A25: S22 | B25: 46580 | C25: 46593 | D25: P6 | E25: Exams, marks, results | G25: Planned
A26: S23 | B26: 46594 | C26: 46607 | D26: P6 | E26: Exams, marks, results | G26: Planned
A27: S24 | B27: 46608 | C27: 46621 | D27: P6, P7 | E27: Exams, marks, results + Fees, payments, finance | F27: Academic Pilot | G27: Planned
A28: S25 | B28: 46622 | C28: 46635 | D28: P7 | E28: Fees, payments, finance | G28: Planned
A29: S26 | B29: 46636 | C29: 46649 | D29: P7 | E29: Fees, payments, finance | G29: Planned
A30: S27 | B30: 46650 | C30: 46663 | D30: P7 | E30: Fees, payments, finance | G30: Planned
A31: S28 | B31: 46664 | C31: 46677 | D31: P7, P8 | E31: Fees, payments, finance + HR, payroll, leave | G31: Planned
A32: S29 | B32: 46678 | C32: 46691 | D32: P8 | E32: HR, payroll, leave | F32: School Beta | G32: Planned
A33: S30 | B33: 46692 | C33: 46705 | D33: P8 | E33: HR, payroll, leave | G33: Planned
A34: S31 | B34: 46706 | C34: 46719 | D34: P8, P9 | E34: HR, payroll, leave + Library, transport, hostel, medical | G34: Planned
A35: S32 | B35: 46720 | C35: 46733 | D35: P9 | E35: Library, transport, hostel, medical | G35: Planned
A36: S33 | B36: 46734 | C36: 46747 | D36: P9, P10 | E36: Library, transport, hostel, medical + Offline, backup, resilience | G36: Planned
A37: S34 | B37: 46748 | C37: 46761 | D37: P9, P10 | E37: Library, transport, hostel, medical + Offline, backup, resilience | G37: Planned
A38: S35 | B38: 46762 | C38: 46775 | D38: P10 | E38: Offline, backup, resilience | F38: Feature Complete | G38: Planned
A39: S36 | B39: 46776 | C39: 46789 | D39: P10, P11 | E39: Offline, backup, resilience + Analytics, automation, AI | G39: Planned
A40: S37 | B40: 46790 | C40: 46803 | D40: P11 | E40: Analytics, automation, AI | F40: Resilience Gate | G40: Planned
A41: S38 | B41: 46804 | C41: 46817 | D41: P11 | E41: Analytics, automation, AI | G41: Planned
...

Sheet Release Plan
A1: Release Strategy
A3: Release | B3: Target | C3: Audience | D3: Included Scope | E3: Excluded / Deferred | F3: Entry Criteria | G3: Exit Criteria | H3: Rollback | I3: Support Level | J3: Status
A4: R0 Internal Foundation | B4: 46430 | C4: Development team | D4: Auth, RBAC, campus, academic foundation | E4: Business modules | F4: Architecture gate passed | G4: Foundation automated tests pass | H4: Revert migration in dev | I4: Engineering only | J4: Planned
A5: R1 Student Alpha | B5: 46486 | C5: Internal + school SME | D5: Students, family, admissions, enrollment | E5: Finance/exams | F5: R0 stable | G5: Student lifecycle UAT passes | H5: Snapshot + migration rollback | I5: Internal | J5: Planned
A6: R2 Operations Alpha | B6: 46563 | C6: Internal pilot users | D6: Timetable, attendance, homework, notifications | E6: Finance/AI | F6: R1 stable | G6: Teacher workflows pass | H6: Feature flag / rollback | I6: Pilot | J6: Planned
A7: R3 Academic Pilot | B7: 46619 | C7: Selected school pilot | D7: Exams, marks, results | E7: Finance full suite | F7: R2 stable | G7: Exam lifecycle passes | H7: Restore snapshot + app rollback | I7: Pilot | J7: Planned
A8: R4 School Beta | B8: 46682 | C8: Broader school team | D8: Finance/payments + core academic | E8: Advanced optional modules | F8: Financial test pack passes | G8: Reconciliation/UAT pass | H8: DB backup + app rollback | I8: Beta | J8: Planned
A9: R5 Feature Complete | B9: 46766 | C9: Pilot customer | D9: HR + optional modules | E9: AI advanced | F9: R4 stable | G9: Module acceptance passes | H9: Module flags + backup | I9: Beta | J9: Planned
A10: R6 Release Candidate | B10: 46829 | C10: Production-like pilot | D10: Offline, backup, analytics, automation, AI | E10: Deferred features | F10: Resilience gate passed | G10: Zero critical defects | H10: Full restore rehearsal | I10: RC | J10: Planned
A11: R7 GA | B11: 46860 | C11: Production customers | D11: Full planned release | E11: GPS/biometrics/inventory/WhatsApp/payment gateway | F11: GA readiness gate | G11: Go/no-go approved | H11: Documented production rollback | I11: Production | J11: Planned

Sheet Module Scope
A1: Module Scope & Release Mapping
A3: Module | B3: Category | C3: Priority | D3: Planned Phase | E3: Release | F3: Optional? | G3: Current Decision | H3: Key Notes
A4: SaaS Control Plane | B4: Platform | C4: Critical | D4: P1 | E4: R0 | F4: No | G4: Planned | H4: School routing, project/version metadata; no school operational data
A5: Authentication | B5: Foundation | C5: Critical | D5: P2 | E5: R0 | F5: No | G5: Confirmed | H5: Email or admin-created username; school-generated ID retained
A6: People & Accounts | B6: Foundation | C6: Critical | D6: P2 | E6: R0 | F6: No | G6: Confirmed | H6: Person separated from login; one person may have multiple roles
A7: Roles/Permissions/Scopes | B7: Foundation | C7: Critical | D7: P2 | E7: R0 | F7: No | G7: Confirmed | H7: Action + scope + approval authority
A8: School Configuration | B8: Foundation | C8: Critical | D8: P2 | E8: R0 | F8: No | G8: Confirmed | H8: Name, code, logo, currency, timezone, numbering rules
A9: Campuses | B9: Foundation | C9: Critical | D9: P2 | E9: R0 | F9: No | G9: Confirmed | H9: Separate campus scope with senior cross-campus view
A10: Academic Years | B10: Academic | C10: Critical | D10: P2 | E10: R0 | F10: No | G10: Confirmed | H10: History preserved; active-year and multi-year access
A11: Classes/Sections/Rooms | B11: Academic | C11: Critical | D11: P2 | E11: R0 | F11: No | G11: Confirmed | H11: Configurable levels, capacity, roll numbering
A12: Students/Families | B12: Student | C12: Critical | D12: P3 | E12: R1 | F12: No | G12: Confirmed | H12: Shared family account and multiple children
A13: Admissions | B13: Student | C13: High | D13: P3 | E13: R1 | F13: No | G13: Confirmed | H13: Configurable stages; some stages may be skipped
A14: Enrollment/Promotion | B14: Student | C14: Critical | D14: P3 | E14: R1 | F14: No | G14: Confirmed | H14: New enrollment record each year; preserve history
... A34: GPS/Biometrics/WhatsApp/Payment Gateway | B34: Deferred | C34: Low | D34: Future | E34: Future | F34: Optional | G34: Deferred | H34: Architecture should not block later work

Sheet Risks
A1: Risk Register
A3: ID | B3: Risk | C3: Category | D3: Probability | E3: Impact | F3: Score | G3: Owner | H3: Mitigation | I3: Trigger / Indicator | J3: Contingency | K3: Status | L3: Review Date
A4: R-01 | B4: Scope grows faster than delivery capacity | C4: Scope | D4: 4 | E4: 5 | F4: 20 | G4: Product Owner | H4: Use module/release gates; defer non-core features | I4: Frequent additions inside active sprint | J4: Move feature to later release | K4: Open | L4: 46297
A5: R-02 | B5: Premature schema decisions create expensive migrations | C5: Architecture | D5: 3 | E5: 5 | F5: 15 | G5: Lead Engineer | H5: Design dependency order; ADRs; migration rehearsal | I5: Repeated destructive migrations | J5: Pause feature work and refactor foundation | K5: Open | L5: 46311
A6: R-03 | B6: RLS misconfiguration exposes sensitive school data | C6: Security | D6: 2 | E6: 5 | F6: 10 | G6: Lead Engineer | H6: Default deny; automated permission tests; security review | I6: Unexpected cross-role access | J6: Disable affected feature and patch policy | K6: Open | L6: 46367
A7: R-04 | B7: Offline conflicts corrupt attendance or finance | C7: Data | D7: 3 | E7: 5 | F7: 15 | G7: Lead Engineer | H7: Conflict detection; idempotency; no silent last-write-wins | I7: Duplicate/conflicting sync events | J7: Quarantine conflicts for admin resolution | K7: Open | L7: 46736
A8: R-05 | B8: Financial corrections become untraceable | C8: Finance | D8: 2 | E8: 5 | F8: 10 | G8: Lead Engineer | H8: No hard delete; reversal + approval + audit | I8: Manual database edits requested | J8: Restrict direct SQL and reconcile ledger | K8: Open | L8: 46614
A9: R-06 | B9: One-person development becomes schedule bottleneck | C9: Resource | D9: 4 | E9: 4 | F9: 16 | G9: Product Owner | H9: Keep priorities strict; automate testing; document architecture | I9: Critical path slips >2 sprints | J9: Add QA/dev support or move release date | K9: Open | L9: 46327
A10: R-07 | B10: AI reveals data user cannot normally access | C10: AI/Security | D10: 2 | E10: 5 | F10: 10 | G10: Lead Engineer | H10: AI uses permission-aware query/service layer | I10: AI response contains unauthorized fields | J10: Disable AI endpoint and audit access | K10: Open | L10: 46798
A11: R-08 | B11: Generated reports/PDFs consume excessive storage | C11: Storage | D11: 1 | E11: 3 | F11: 3 | G11: Lead Engineer | H11: Generate on demand; do not auto-store generated PDFs | I11: Bucket growth exceeds plan | J11: Purge temporary files | K11: Open | L11: 46600
A12: R-09 | B12: Uploaded documents exceed storage or performance limits | C12: Storage | D12: 3 | E12: 3 | F12: 9 | G12: Lead Engineer | H12: Compress/resize; 1 MB limit; structured buckets | I12: High rejection/compression failure rate | J12: Adjust supported file strategy | K12: Open | L12: 46461
A13: R-10 | B13: Timetable auto-generation complexity delays release | C13: Algorithm | D13: 3 | E13: 3 | F13: 9 | G13: Lead Engineer | H13: Manual timetable remains supported; stage optimizer | I13: Generator fails valid schedules | J13: Ship manual-first with assisted conflict detection | K13: Open | L13: 46478
A14: R-11 | B14: Shared family login weakens action attribution | C14: Security | D14: 3 | E14: 3 | F14: 9 | G14: Product Owner | H14: Treat as family role by design; log account/device/session | I14: Dispute over who submitted action | J14: Require confirmation for sensitive parent actions | K14: Accepted | L14: 46433
A15: R-12 | B15: Email app-password setup becomes unreliable | C15: Integration | D15: 3 | E15: 3 | F15: 9 | G15: Lead Engineer | H15: Abstract email provider; later support managed provider | I15: Delivery failures/bounces | J15: Switch provider without changing domain logic | K15: Open | L15: 46539
... A23: R-20 | B23: Supabase plan limits or costs change | C23: Vendor | D23: 2 | E23: 4 | F23: 8 | G23: Product Owner | H23: Monitor usage/cost; keep portable PostgreSQL schema | I23: Unexpected cost growth | J23: Tune usage or revise deployment tier | K23: Open | L23: 46661

Sheet RACI
A1: RACI Responsibility Matrix
A3: Activity | B3: Product Owner | C3: Lead Engineer | D3: QA | E3: School SME | F3: Exam Controller | G3: Finance/Admin | H3: Ops/Support
A4: Requirements & scope | B4: A | C4: R | D4: C | E4: C | F4: C | G4: C | H4: I
A5: Architecture decisions | B5: C | C5: A/R | D5: C | E5: I | F5: I | G5: I | H5: I
A6: Database schema & migrations | B6: I | C6: A/R | D6: C | E6: I | F6: I | G6: I | H6: I
A7: Security/RLS model | B7: I | C7: A/R | D7: C | E7: I | F7: I | G7: I | H7: I
A8: UX/workflow validation | B8: A | C8: R | D8: C | E8: C | F8: C | G8: C | H8: I
A9: Academic configuration | B9: I | C9: R | D9: C | E9: A/C | F9: C | G9: I | H9: I
A10: Attendance acceptance | B10: I | C10: R | D10: C | E10: A/C | F10: I | G10: I | H10: I
A11: Exam/result workflow | B11: I | C11: R | D11: C | E11: C | F11: A | G11: I | H11: I
A12: Finance workflow | B12: I | C12: R | D12: C | E12: C | F12: I | G12: A/C | H12: I
A13: HR/payroll workflow | B13: I | C13: R | D13: C | E13: C | F13: I | G13: A/C | H13: I
A14: Release testing | B14: I | C14: R | D14: A | E14: C | F14: C | G14: C | H14: I
... A18: Change control | B18: A | C18: R | D18: C | E18: C | F18: C | G18: C | H18: I

Sheet QA & Gates
A1: Quality, Test & Release Gates
A3: Area | B3: Minimum Test Scope | C3: When | D3: Owner | E3: Automate? | F3: Blocking? | G3: Pass Criteria | H3: Evidence | I3: Status | J3: Notes
A4: Database migrations | B4: Fresh install + upgrade from previous schema | C4: Every migration | D4: Lead Engineer | E4: Yes | F4: Yes | G4: Repeatable, no data loss | H4: CI logs / migration report | I4: Planned
A5: RLS / authorization | B5: Positive + negative role/scope tests | C5: Every security change | D5: Lead Engineer / QA | E5: Yes | F5: Yes | G5: No unauthorized rows/actions | H5: Automated test report | I5: Planned
A6: Audit | B6: Sensitive actions create immutable audit trail | C6: Per module | D6: QA | E6: Yes | F6: Yes | G6: Actor/action/time/old/new/reason captured | H6: Audit test evidence | I6: Planned
A7: Approvals | B7: Request/approve/reject/cancel/retry workflows | C7: Per module | D7: QA | E7: Yes | F7: Yes | G7: No bypass of required approval | H7: Workflow test report | I7: Planned
A8: Attendance | B8: Morning/break/manual/QR/correction/offline | C8: P5/P10 | D8: QA + SME | E8: Mixed | F8: Yes | G8: All attendance scenarios reconcile | H8: Scenario checklist | I8: Planned
A9: Exams/results | B9: Entry/correction/review/publish/lock | C9: P6 | D9: QA + Exam Controller | E9: Mixed | F9: Yes | G9: Published result lifecycle correct | H9: UAT sign-off | I9: Planned
A10: Finance | B10: Invoice/payment/reversal/advance/discount/reconciliation | C10: P7 | D10: QA + Finance | E10: Mixed | F10: Yes | G10: Ledger/report totals reconcile | H10: Finance test pack | I10: Planned
A11: Payroll | B11: Monthly calc/bonus/deduction/approval/lock | C11: P8 | D11: QA + Admin | E11: Mixed | F11: Yes | G11: Payslip totals reconcile | H11: Payroll test pack | I11: Planned
A12: Storage | B12: Private access, compression, 1 MB policy | C12: P3/P9 | D12: QA | E12: Yes | F12: Yes | G12: Unauthorized files inaccessible | H12: Storage policy tests | I12: Planned
A13: Offline sync | B13: Queue/idempotency/conflict resolution | C13: P10 | D13: QA | E13: Yes | F13: Yes | G13: No silent critical overwrites | H13: Sync stress test | I13: Planned
A14: Backup/restore | B14: Restore latest backup in isolated environment | C14: P10/P12 | D14: Lead Engineer / QA | E14: Mixed | F14: Yes | G14: Recovery runbook passes | H14: Restore report | I14: Planned
A15: Performance | B15: Key workflows at realistic school size | C15: P12 | D15: QA | E15: Mixed | F15: Yes | G15: Targets agreed and met | H15: Load test report | I15: Planned
... A18: Release rollback | B18: App + DB rollback/recovery rehearsal | C18: R6/R7 | D18: Lead Engineer / QA | E18: Mixed | F18: Yes | G18: Rollback/recovery documented and proven | H18: Runbook | I18: Planned

Sheet Change Log
A1: Project Change & Decision Log
A3: ID | B3: Date | C3: Type | D3: Decision / Change | E3: Reason | F3: Impact | G3: Approved By | H3: Status | I3: Version / Reference
A4: D-001 | B4: 46284 | C4: Architecture | D4: Use SaaS deployment model | E4: Product intended for distribution | F4: Introduces control plane and repeatable deployment | G4: Product Owner | H4: Approved | I4: Requirements v0.1
A5: D-002 | B5: 46284 | C5: Architecture | D5: One school = one Supabase project | E5: Stronger tenant isolation and simpler school RLS | F5: Requires per-school provisioning/version management | G5: Product Owner | H5: Approved | I5: Requirements v0.1
A6: D-003 | B6: 46284 | C6: Architecture | D6: Five engines: data, permission, workflow, automation, AI | E6: Avoid disconnected CRUD architecture | F6: Cross-cutting platform design required | G6: Product Owner | H6: Approved | I6: Requirements v0.1
A7: D-004 | B7: 46284 | C7: Security | D7: Financial records are reversed/cancelled, not hard-deleted | E7: Audit/accounting integrity | F7: Requires correction/reversal workflows | G7: Product Owner | H7: Approved | I7: Requirements v0.1
A8: D-005 | B8: 46284 | C8: Product | D8: Generated PDFs are on-demand and not auto-stored | E8: Reduce storage consumption | F8: Need reliable document generators | G8: Product Owner | H8: Approved | I8: Requirements v0.1
A9: D-006 | B9: 46284 | C9: Product | D9: Inventory, GPS, biometrics, WhatsApp and payment gateway deferred | E9: Control initial scope | F9: Keep extension points only | G9: Product Owner | H9: Approved | I9: Requirements v0.1
A10: D-007 | B10: 2026-09-21 | C10: Architecture | D10: Attendance core is capture-method independent; manual and QR are V1 adapters, biometric/camera/RFID/NFC are future adapters | E10: Future attendance hardware must not force redesign of attendance history | F10: Add source/device/event extensibility while deferring biometric/camera implementation | G10: Product Owner | H10: Approved | I10: Codex Environment v0.2

Sheet Gantt
A1: Phase Gantt - Monthly View
H2: 46295 | I2: 46326 | J2: 46356 | K2: 46387 | L2: 46418 | M2: 46446 | N2: 46477 | O2: 46507 | P2: 46538 | Q2: 46568 | R2: 46599 | S2: 46630 | T2: 46660 | U2: 46691 | V2: 46721 | W2: 46752 | X2: 46783 | Y2: 46812 | Z2: 46843 | AA2: 46873
A3: Phase | B3: Name | C3: Start | D3: End | E3: Owner | F3: Status | G3: Progress % | H3: 46266 | I3: 46296 | J3: 46327 | K3: 46357 | L3: 46388 | M3: 46419 | N3: 46447 | O3: 46478 | P3: 46508 | Q3: 46539 | R3: 46569 | S3: 46600 | T3: 46631 | U3: 46661 | V3: 46692 | W3: 46722 | X3: 46753 | Y3: 46784 | Z3: 46813 | AA3: 46844
A4: P0 | B4: Discovery & Project Setup | C4: 46286 | D4: 46311 | E4: Product Owner / Lead | F4: In Progress | G4: 0.75 | H4: =IF(AND(H$3<=$D4,H$2>=$C4),"■","") -> ■ | I4: =IF(AND(I$3<=$D4,I$2>=$C4),"■","") -> ■ | J4: =IF(AND(J$3<=$D4,J$2>=$C4),"■","") | K4: =IF(AND(K$3<=$D4,K$2>=$C4),"■","") | L4: =IF(AND(L$3<=$D4,L$2>=$C4),"■","") | M4: =IF(AND(M$3<=$D4,M$2>=$C4),"■","") | N4: =IF(AND(N$3<=$D4,N$2>=$C4),"■","") | O4: =IF(AND(O$3<=$D4,O$2>=$C4),"■","") | ... AA4: =IF(AND(AA$3<=$D4,AA$2>=$C4),"■","")
A5: P1 | B5: Architecture & SaaS Foundation | C5: 46314 | D5: 46367 | E5: Lead Engineer | F5: Not Started | G5: 0 | H5: =IF(AND(H$3<=$D5,H$2>=$C5),"■","") | I5: =IF(AND(I$3<=$D5,I$2>=$C5),"■","") -> ■ | J5: =IF(AND(J$3<=$D5,J$2>=$C5),"■","") -> ■ | K5: =IF(AND(K$3<=$D5,K$2>=$C5),"■","") -> ■ | L5: =IF(AND(L$3<=$D5,L$2>=$C5),"■","") | M5: =IF(AND(M$3<=$D5,M$2>=$C5),"■","") | N5: =IF(AND(N$3<=$D5,N$2>=$C5),"■","") | O5: =IF(AND(O$3<=$D5,O$2>=$C5),"■","") | ... AA5: =IF(AND(AA$3<=$D5,AA$2>=$C5),"■","")
A6: P2 | B6: Identity, RBAC & Academic Foundation | C6: 46370 | D6: 46430 | E6: Lead Engineer | F6: Not Started | G6: 0 | H6: =IF(AND(H$3<=$D6,H$2>=$C6),"■","") | I6: =IF(AND(I$3<=$D6,I$2>=$C6),"■","") | J6: =IF(AND(J$3<=$D6,J$2>=$C6),"■","") | K6: =IF(AND(K$3<=$D6,K$2>=$C6),"■","") -> ■ | L6: =IF(AND(L$3<=$D6,L$2>=$C6),"■","") -> ■ | M6: =IF(AND(M$3<=$D6,M$2>=$C6),"■","") -> ■ | N6: =IF(AND(N$3<=$D6,N$2>=$C6),"■","") | O6: =IF(AND(O$3<=$D6,O$2>=$C6),"■","") | ... AA6: =IF(AND(AA$3<=$D6,AA$2>=$C6),"■","")
A7: P3 | B7: Students, Families & Admissions | C7: 46433 | D7: 46486 | E7: Lead Engineer | F7: Not Started | G7: 0 | H7: =IF(AND(H$3<=$D7,H$2>=$C7),"■","") | I7: =IF(AND(I$3<=$D7,I$2>=$C7),"■","") | J7: =IF(AND(J$3<=$D7,J$2>=$C7),"■","") | K7: =IF(AND(K$3<=$D7,K$2>=$C7),"■","") | L7: =IF(AND(L$3<=$D7,L$2>=$C7),"■","") | M7: =IF(AND(M$3<=$D7,M$2>=$C7),"■","") -> ■ | N7: =IF(AND(N$3<=$D7,N$2>=$C7),"■","") -> ■ | O7: =IF(AND(O$3<=$D7,O$2>=$C7),"■","") -> ■ | ... AA7: =IF(AND(AA$3<=$D7,AA$2>=$C7),"■","")
A8: P4 | B8: Curriculum, Teachers & Timetable | C8: 46468 | D8: 46521 | E8: Lead Engineer | F8: Not Started | G8: 0 | H8: =IF(AND(H$3<=$D8,H$2>=$C8),"■","") | I8: =IF(AND(I$3<=$D8,I$2>=$C8),"■","") | J8: =IF(AND(J$3<=$D8,J$2>=$C8),"■","") | K8: =IF(AND(K$3<=$D8,K$2>=$C8),"■","") | L8: =IF(AND(L$3<=$D8,L$2>=$C8),"■","") | M8: =IF(AND(M$3<=$D8,M$2>=$C8),"■","") | N8: =IF(AND(N$3<=$D8,N$2>=$C8),"■","") -> ■ | O8: =IF(AND(O$3<=$D8,O$2>=$C8),"■","") -> ■ | ... AA8: =IF(AND(AA$3<=$D8,AA$2>=$C8),"■","")
A9: P5 | B9: Attendance, Homework & Notifications Core | C9: 46503 | D9: 46563 | E9: Lead Engineer | F9: Not Started | G9: 0 | H9: =IF(AND(H$3<=$D9,H$2>=$C9),"■","") | I9: =IF(AND(I$3<=$D9,I$2>=$C9),"■","") | J9: =IF(AND(J$3<=$D9,J$2>=$C9),"■","") | K9: =IF(AND(K$3<=$D9,K$2>=$C9),"■","") | L9: =IF(AND(L$3<=$D9,L$2>=$C9),"■","") | M9: =IF(AND(M$3<=$D9,M$2>=$C9),"■","") | N9: =IF(AND(N$3<=$D9,N$2>=$C9),"■","") | O9: =IF(AND(O$3<=$D9,O$2>=$C9),"■","") -> ■ | ... AA9: =IF(AND(AA$3<=$D9,AA$2>=$C9),"■","")
A10: P6 | B10: Exams, Marks & Results | C10: 46552 | D10: 46619 | E10: Lead Engineer | F10: Not Started | G10: 0 | H10: =IF(AND(H$3<=$D10,H$2>=$C10),"■","") | I10: =IF(AND(I$3<=$D10,I$2>=$C10),"■","") | J10: =IF(AND(J$3<=$D10,J$2>=$C10),"■","") | K10: =IF(AND(K$3<=$D10,K$2>=$C10),"■","") | L10: =IF(AND(L$3<=$D10,L$2>=$C10),"■","") | M10: =IF(AND(M$3<=$D10,M$2>=$C10),"■","") | N10: =IF(AND(N$3<=$D10,N$2>=$C10),"■","") | O10: =IF(AND(O$3<=$D10,O$2>=$C10),"■","") | ... AA10: =IF(AND(AA$3<=$D10,AA$2>=$C10),"■","")
A11: P7 | B11: Fees, Payments & Finance | C11: 46608 | D11: 46682 | E11: Lead Engineer | F11: Not Started | G11: 0 | H11: =IF(AND(H$3<=$D11,H$2>=$C11),"■","") | I11: =IF(AND(I$3<=$D11,I$2>=$C11),"■","") | J11: =IF(AND(J$3<=$D11,J$2>=$C11),"■","") | K11: =IF(AND(K$3<=$D11,K$2>=$C11),"■","") | L11: =IF(AND(L$3<=$D11,L$2>=$C11),"■","") | M11: =IF(AND(M$3<=$D11,M$2>=$C11),"■","") | N11: =IF(AND(N$3<=$D11,N$2>=$C11),"■","") | O11: =IF(AND(O$3<=$D11,O$2>=$C11),"■","") | ... AA11: =IF(AND(AA$3<=$D11,AA$2>=$C11),"■","")
A12: P8 | B12: HR, Payroll & Leave | C12: 46664 | D12: 46717 | E12: Lead Engineer | F12: Not Started | G12: 0 | H12: =IF(AND(H$3<=$D12,H$2>=$C12),"■","") | I12: =IF(AND(I$3<=$D12,I$2>=$C12),"■","") | J12: =IF(AND(J$3<=$D12,J$2>=$C12),"■","") | K12: =IF(AND(K$3<=$D12,K$2>=$C12),"■","") | L12: =IF(AND(L$3<=$D12,L$2>=$C12),"■","") | M12: =IF(AND(M$3<=$D12,M$2>=$C12),"■","") | N12: =IF(AND(N$3<=$D12,N$2>=$C12),"■","") | O12: =IF(AND(O$3<=$D12,O$2>=$C12),"■","") | ... AA12: =IF(AND(AA$3<=$D12,AA$2>=$C12),"■","")
A13: P9 | B13: Library, Transport, Hostel & Medical | C13: 46699 | D13: 46766 | E13: Lead Engineer | F13: Not Started | G13: 0 | H13: =IF(AND(H$3<=$D13,H$2>=$C13),"■","") | I13: =IF(AND(I$3<=$D13,I$2>=$C13),"■","") | J13: =IF(AND(J$3<=$D13,J$2>=$C13),"■","") | K13: =IF(AND(K$3<=$D13,K$2>=$C13),"■","") | L13: =IF(AND(L$3<=$D13,L$2>=$C13),"■","") | M13: =IF(AND(M$3<=$D13,M$2>=$C13),"■","") | N13: =IF(AND(N$3<=$D13,N$2>=$C13),"■","") | O13: =IF(AND(O$3<=$D13,O$2>=$C13),"■","") | ... AA13: =IF(AND(AA$3<=$D13,AA$2>=$C13),"■","")
A14: P10 | B14: Offline Sync, Backup & Hardening | C14: 46734 | D14: 46794 | E14: Lead Engineer / QA | F14: Not Started | G14: 0 | H14: =IF(AND(H$3<=$D14,H$2>=$C14),"■","") | I14: =IF(AND(I$3<=$D14,I$2>=$C14),"■","") | J14: =IF(AND(J$3<=$D14,J$2>=$C14),"■","") | K14: =IF(AND(K$3<=$D14,K$2>=$C14),"■","") | L14: =IF(AND(L$3<=$D14,L$2>=$C14),"■","") | M14: =IF(AND(M$3<=$D14,M$2>=$C14),"■","") | N14: =IF(AND(N$3<=$D14,N$2>=$C14),"■","") | O14: =IF(AND(O$3<=$D14,O$2>=$C14),"■","") | ... AA14: =IF(AND(AA$3<=$D14,AA$2>=$C14),"■","")
A15: P11 | B15: Analytics, Automation & AI | C15: 46769 | D15: 46829 | E15: Lead Engineer | F15: Not Started | G15: 0 | H15: =IF(AND(H$3<=$D15,H$2>=$C15),"■","") | I15: =IF(AND(I$3<=$D15,I$2>=$C15),"■","") | J15: =IF(AND(J$3<=$D15,J$2>=$C15),"■","") | K15: =IF(AND(K$3<=$D15,K$2>=$C15),"■","") | L15: =IF(AND(L$3<=$D15,L$2>=$C15),"■","") | M15: =IF(AND(M$3<=$D15,M$2>=$C15),"■","") | N15: =IF(AND(N$3<=$D15,N$2>=$C15),"■","") | O15: =IF(AND(O$3<=$D15,O$2>=$C15),"■","") | ... AA15: =IF(AND(AA$3<=$D15,AA$2>=$C15),"■","")
A16: P12 | B16: UAT, Security, Performance & Launch | C16: 46813 | D16: 46857 | E16: Lead Engineer / QA | F16: Not Started | G16: 0 | H16: =IF(AND(H$3<=$D16,H$2>=$C16),"■","") | I16: =IF(AND(I$3<=$D16,I$2>=$C16),"■","") | J16: =IF(AND(J$3<=$D16,J$2>=$C16),"■","") | K16: =IF(AND(K$3<=$D16,K$2>=$C16),"■","") | L16: =IF(AND(L$3<=$D16,L$2>=$C16),"■","") | M16: =IF(AND(M$3<=$D16,M$2>=$C16),"■","") | N16: =IF(AND(N$3<=$D16,N$2>=$C16),"■","") | O16: =IF(AND(O$3<=$D16,O$2>=$C16),"■","") | ... AA16: =IF(AND(AA$3<=$D16,AA$2>=$C16),"■","") -> ■

Sheet Dashboard
A1: School OS SaaS - Project Management Dashboard
A3: Metric | B3: Value | D3: Phase | E3: Status | F3: Progress % | G3: Weeks | I3: Task Status | J3: Count
A4: Project Start | B4: 46286 | D4: P0 | E4: In Progress | F4: 0.75 | G4: 4 | I4: Not Started | J4: =COUNTIF('Task Register'!J4:J111,I4) -> 105
A5: Target GA | B5: 46860 | D5: P1 | E5: Not Started | F5: 0 | G5: 8 | I5: In Progress | J5: =COUNTIF('Task Register'!J4:J111,I5) -> 0
A6: Total Planned Tasks | B6: 108 | D6: P2 | E6: Not Started | F6: 0 | G6: 9 | I6: At Risk | J6: =COUNTIF('Task Register'!J4:J111,I6) -> 0
A7: Tasks Done | B7: =COUNTIF('Task Register'!J4:J111,"Done") -> 3 | D7: P3 | E7: Not Started | F7: 0 | G7: 8 | I7: Blocked | J7: =COUNTIF('Task Register'!J4:J111,I7) -> 0
A8: Tasks In Progress | B8: =COUNTIF('Task Register'!J4:J111,"In Progress") -> 0 | D8: P4 | E8: Not Started | F8: 0 | G8: 8 | I8: Done | J8: =COUNTIF('Task Register'!J4:J111,I8) -> 3
A9: Tasks At Risk/Blocked | B9: =COUNTIF('Task Register'!J4:J111,"At Risk")+COUNTIF('Task Register'!J4:J111,"Blocked") -> 0 | D9: P5 | E9: Not Started | F9: 0 | G9: 9
A10: Overall Completion | B10: =SUM('Task Register'!K4:K111)/108 -> 0.027777778 | D10: P6 | E10: Not Started | F10: 0 | G10: 10
A11: Open / Mitigating Risks | B11: =COUNTIF(Risks!K4:K23,"Open")+COUNTIF(Risks!K4:K23,"Mitigating") -> 19 | D11: P7 | E11: Not Started | F11: 0 | G11: 11
A12: High/Critical Risks (score >=15) | B12: =COUNTIF(Risks!F4:F23,">=15") -> 6 | D12: P8 | E12: Not Started | F12: 0 | G12: 8
A13: Next Major Gate | B13: Architecture Gate | D13: P9 | E13: Not Started | F13: 0 | G13: 10
D14: P10 | E14: Not Started | F14: 0 | G14: 9
A15: Management Notes | D15: P11 | E15: Not Started | F15: 0 | G15: 9
A16: Current focus | B16: Freeze architecture before production schema build | D16: P12 | E16: Not Started | F16: 0 | G16: 7
A17: Cadence | B17: Two-week sprints; weekly risk review; milestone gate at phase end
A18: Change rule | B18: No major scope added to active sprint without explicit trade-off
A19: Security rule | B19: RLS/default-deny and approval/audit requirements are release blockers
A20: Finance rule | B20: No destructive deletion of financial transactions
A21: AI rule | B21: AI must use the same permission boundaries as the application

Sheet README
A1: How to Use This Project Management Workbook
A3: Sheet | B3: Purpose | C3: Update Frequency | D3: Primary Owner | E3: What to Edit | F3: Important Rule
A4: Dashboard | B4: Executive status, task counts, risks, phase progress | C4: Weekly | D4: Product Owner | E4: Mostly automatic; update task/risk sheets | F4: Do not manually overwrite KPI formulas
A5: Roadmap | B5: High-level phases and baseline dates | C5: At phase planning/change approval | D5: Product Owner / Lead | E5: Dates, owner, status, progress | F5: Change dates only through approved replan
A6: Task Register | B6: Detailed WBS and delivery tracking | C6: Daily/weekly | D6: Lead Engineer | E6: Status, progress, dates, notes | F6: Every task needs an acceptance criterion
A7: Gantt | B7: Monthly visual of roadmap | C7: At roadmap change | D7: Product Owner | E7: Phase dates if deliberately replanned | F7: Use as presentation view, not the detailed tracker
A8: Sprints | B8: Two-week sprint calendar | C8: Every sprint | D8: Lead Engineer | E8: Focus, status, notes | F8: Do not overload sprint with deferred modules
A9: Milestones | B9: Release and architecture gates | C9: At gate review | D9: Product Owner | E9: Status and evidence | F9: No gate passes without evidence
A10: Release Plan | B10: Alpha/beta/RC/GA scope | C10: Before each release | D10: Product Owner | E10: Scope and criteria | F10: Excluded scope stays excluded unless change approved
A11: Module Scope | B11: Module priorities and release mapping | C11: Monthly | D11: Product Owner | E11: Priority/release/decision | F11: Prevents scope creep
A12: Risks | B12: Risk register and mitigation | C12: Weekly | D12: Product Owner / Lead | E12: Probability, impact, mitigation, status | F12: Escalate score >=15
A13: RACI | B13: Responsibility matrix | C13: When team changes | D13: Product Owner | E13: Responsibility cells | F13: Keep accountability clear
A14: QA & Gates | B14: Quality criteria and release blockers | C14: Per sprint/release | D14: QA / Lead | E14: Status/evidence/notes | F14: Blocking tests must pass
... A16: Assumptions | B16: Planning assumptions behind dates | C16: When assumptions change | D16: Product Owner | E16: Baseline assumptions | F16: Re-estimate when capacity/scope changes

Sheet Future Roadmap
A1: School OS SaaS - Future / Advanced Feature Roadmap
A3: ID | B3: Future Feature | C3: Domain | D3: Priority Later | E3: Current Status | F3: Architecture Requirement Now | G3: Likely Integration Pattern | H3: Dependencies | I3: Risk / Complexity | J3: Notes
A4: F-001 | B4: Fingerprint / biometric attendance devices | C4: Attendance | D4: High | E4: Deferred | F4: Attendance core must be capture-method independent; preserve device/event IDs and source metadata | G4: Device adapter -> validated attendance event -> attendance service | H4: Attendance, device registry, identity mapping, sync | I4: High | J4: Vendor SDK/protocol differences; privacy and biometric governance required
A5: F-002 | B5: Camera / face-recognition attendance | C5: Attendance | D5: High | E5: Deferred | F5: Do not couple attendance table to QR/manual; allow camera-generated recognition events and confidence metadata | G5: Camera/vision service -> recognition event -> human/rule validation -> attendance service | H5: Attendance, device registry, media/AI service, identity mapping | I5: Very High | J5: Requires privacy, consent/legal review, anti-spoofing, model accuracy and hardware planning
A6: F-003 | B6: RFID / NFC attendance | C6: Attendance | D6: Medium | E6: Deferred | F6: Student identifiers/cards should support external token mapping | G6: Reader adapter -> token event -> identity resolution -> attendance service | H6: Student cards, device registry, attendance | I6: Medium | J6: Reader hardware and card lifecycle
A7: F-004 | B7: Advanced QR anti-fraud | C7: Attendance | D7: Medium | E7: Deferred | F7: QR token strategy should allow rotation/versioning and optional confirmation | G7: Scanner -> signed/rotating token validation -> attendance | H7: QR attendance, student cards | I7: Medium | J7: May add photo/device confirmation
A8: F-005 | B8: Live bus GPS tracking | C8: Transport | D8: Medium | E8: Deferred | F8: Transport model should use stable vehicle/route/student assignments independent of tracking provider | G8: GPS provider adapter -> telemetry stream -> transport tracking service | H8: Vehicles, routes, parent notifications | I8: High | J8: Realtime location cost, privacy, provider variance
A9: F-006 | B9: WhatsApp messaging | C9: Notifications | D9: Medium | E9: Deferred | F9: Notification engine must use provider/channel adapters | G9: Notification event -> WhatsApp provider adapter | H9: Notifications, templates, consent | I9: Medium | J9: Provider pricing, template approval, opt-in
A10: F-007 | B10: Direct payment gateway | C10: Finance | D10: High | E10: Deferred | F10: Payment ledger must support externally confirmed payments without changing financial core | G10: Gateway webhook -> payment verification -> ledger/receipt | H10: Payments, finance, webhook security | I10: High | J10: Idempotency, refunds, reconciliation
A11: F-008 | B11: Inventory / asset management | C11: Operations | D11: Medium | E11: Deferred | F11: No dependency required in student core; keep module boundaries clean | G11: Optional module | H11: Procurement/HR/rooms | I11: Medium | J11: Large independent domain
A12: F-009 | B12: IoT / smart classroom integration | C12: Platform | D12: Low | E12: Deferred | F12: Use device registry + event adapter concepts rather than embedding vendor fields | G12: Device gateway -> event bus/service | H12: Rooms, timetable, automation | I12: Very High | J12: Vendor fragmentation
A13: F-010 | B13: CCTV integrations | C13: Security | D13: Low | E13: Deferred | F13: Keep out of core operational schema; integrate by references/events only | G13: External surveillance integration | H13: Security policies | I13: Very High | J13: Privacy/security/legal implications
A14: F-011 | B14: Government reporting integrations | C14: Reporting | D14: Medium | E14: Deferred | F14: Reporting layer should expose stable canonical data views | G14: Export/API adapters | H14: Student, academic, finance depending jurisdiction | I14: High | J14: Jurisdiction-specific schemas
... A19: F-016 | B19: Digital certificate verification / blockchain | C19: Documents | D19: Low | E19: Deferred | F19: Generated certificate IDs and verification metadata should be stable | G19: Verification service | H19: Certificates, documents | I19: Medium | J19: Blockchain may not be necessary; keep provider-neutral
